<?xml version="1.0"?>
<robot xmlns:xacro="http://www.ros.org/wiki/xacro">

    <xacro:include filename="inertial_macros.xacro"/>

    <!-- ARM -->
    <!--base-->
    <joint name="base_joint_z" type="revolute">
        <parent link="chassi_link"/>
        <child link="base_mn_link"/>
        <origin xyz="0.1 -0.05 0.12" rpy="0 0 0"/>
        <axis xyz="0 0 1"/>
        <limit effort="1000.0" lower="-1.5708" upper="1.5708" velocity="0.5"/>
    </joint>

    <link name="base_mn_link">
        <xacro:inertial_box mass="0.1" x="0.05" y="0.05" z="0.1">
            <origin xyz="0 0 0" rpy="0 0 0"/>
        </xacro:inertial_box>
    </link>

    <!--link1-->
    <joint name="mn_joint1" type="fixed">
        <parent link="base_mn_link"/>
        <child link="mn_link1"/>
        <origin xyz="0 0 0" rpy="0 0 0"/>
    </joint>

    <link name="mn_link1">
        <visual>
            <origin xyz="0 0 0.125" rpy="0 0 ${pi/2}"/>
            <geometry>
                <box size="0.05 0.05 0.25"/>
            </geometry>
            <material name="blue"/>
        </visual>
        <collision>
            <origin xyz="0 0 0.125" rpy="0 0 ${pi/2}"/>
            <geometry>
                <box size="0.05 0.05 0.25"/>
            </geometry>
        </collision>
        <xacro:inertial_box mass="0.1" x="0.05" y="0.05" z="0.25">
            <origin xyz="0 0 0.125" rpy="0 0 0"/>
        </xacro:inertial_box>
    </link>

    <gazebo reference="mn_link1">
        <material>Gazebo/Blue</material>
    </gazebo>

    <!--link2-->
    <joint name="mn_joint2" type="revolute">
        <parent link="mn_link1"/>
        <child link="mn_link2"/>
        <origin xyz="0 0.05 0.2" rpy="0 0 0"/>
        <axis xyz="0 1 0"/>
        <limit effort="1000.0" lower="0.0" upper="1.5708" velocity="0.5"/>
    </joint>

    <link name="mn_link2">
        <visual>
            <origin xyz="0 0 0.15" rpy="0 0 ${pi/2}"/>
            <geometry>
                <box size="0.05 0.05 0.3"/>
            </geometry>
            <material name="grey"/>
        </visual>
        <collision>
            <origin xyz="0 0 0.15" rpy="0 0 ${pi/2}"/>
            <geometry>
                <box size="0.05 0.05 0.3"/>
            </geometry>
        </collision>
        <xacro:inertial_box mass="0.1" x="0.05" y="0.05" z="0.3">
            <origin xyz="0 0 0.15" rpy="0 0 0"/>
        </xacro:inertial_box>
    </link>

    <gazebo reference="mn_link2">
        <material>Gazebo/Grey</material>
    </gazebo>

    <!--link3-->
    <joint name="mn_joint3" type="revolute">
        <parent link="mn_link2"/>
        <child link="mn_link3"/>
        <origin xyz="0 0.05 0.3" rpy="0 0 0"/>
        <axis xyz="0 0 1"/>
        <limit effort="1000.0" lower="0.0" upper="1.5708" velocity="0.5"/>
    </joint>

    <link name="mn_link3">
        <xacro:inertial_box mass="0.1" x="0.05" y="0.05" z="0.1">
            <origin xyz="0 0 0" rpy="0 0 0"/>
        </xacro:inertial_box>
    </link>

    <!--link4-->
    <joint name="mn_joint4" type="revolute">
        <parent link="mn_link3"/>
        <child link="mn_link4"/>
        <origin xyz="0 0 0" rpy="0 0 0"/>
        <axis xyz="0 1 0"/>
        <limit effort="1000.0" lower="0.0" upper="1.5708" velocity="0.5"/>
    </joint>

    <link name="mn_link4">
        <visual>
            <origin xyz="0 0 0.15" rpy="0 0 ${pi/2}"/>
            <geometry>
                <box size="0.05 0.05 0.3"/>
            </geometry>
            <material name="blue"/>
        </visual>
        <collision>
            <origin xyz="0 0 0.15" rpy="0 0 ${pi/2}"/>
            <geometry>
                <box size="0.05 0.05 0.3"/>
            </geometry>
        </collision>
        <xacro:inertial_box mass="0.1" x="0.05" y="0.05" z="0.3">
            <origin xyz="0 0 0.15" rpy="0 0 0"/>
        </xacro:inertial_box>
    </link>

    <gazebo reference="mn_link4">
        <material>Gazebo/Blue</material>
    </gazebo>

    <!--end effector-->
    <joint name="mn_joint5" type="revolute">
        <parent link="mn_link4"/>
        <child link="mn_link5"/>
        <origin xyz="0 0 0.31" rpy="0 0 0"/>
        <axis xyz="0 0 1"/>
        <limit effort="1000.0" lower="0.0" upper="1.5708" velocity="0.5"/>
    </joint>

    <link name="mn_link5">
        <visual>
            <origin xyz="0 0 0" rpy="0 0 ${pi/2}"/>
            <geometry>
                <box size="0.1 0.05 0.015"/>
            </geometry>
            <material name="grey"/>
        </visual>
        <collision>
            <origin xyz="0 0 0" rpy="0 0 ${pi/2}"/>
            <geometry>
                <box size="0.1 0.05 0.015"/>
            </geometry>
        </collision>
        <xacro:inertial_box mass="0.1" x="0.1" y="0.05" z="0.015">
            <origin xyz="0 0 0" rpy="0 0 0"/>
        </xacro:inertial_box>
    </link>

    <gazebo reference="mn_link5">
        <material>Gazebo/Grey</material>
    </gazebo>

    <!-- ################################### -->
    <joint name="end_fixed_obj" type="fixed">
        <parent link="mn_link5"/>
        <child link="coke_obj"/>
        <origin xyz="0.22 0.01 0.045" rpy="0 -${pi/2} 0"/>
    </joint>

    <link name="coke_obj">
        <visual>
            <geometry>
                <mesh filename="model://coke_can/meshes/coke_can.dae"/>
            </geometry>
        </visual>
        <xacro:inertial_box mass="0.1" x="0.1" y="0.1" z="0.1">
            <origin xyz="0 0 0" rpy="0 0 0"/>
        </xacro:inertial_box>
    </link>
    <!-- ################################### -->


    <!--left gripper-->
    <joint name="left_gripper_joint" type="prismatic">
        <parent link="mn_link5"/>
        <child link="left_gripper_link"/>
        <origin xyz="0.0 0.05 0.045" rpy="0 0 0"/>
        <axis xyz="0 -1 0"/>
        <limit effort="100" lower="0.0" upper="0.03" velocity="100"/>
    </joint>

    <transmission name="left_gripper_tr">
        <type>transmission_interface/SimpleTransmission</type>
        <joint name="left_gripper_joint">
            <hardwareInterface>hardware_interface/EffortJointInterface</hardwareInterface>
        </joint>
        <actuator name="motor_left_gripper">
            <hardwareInterface>hardware_interface/EffortJointInterface</hardwareInterface>
            <mechanicalReduction>1</mechanicalReduction>
        </actuator>
    </transmission>

    <link name="left_gripper_link">
        <visual>
            <origin xyz="0 0 0" rpy="0 0 ${pi/2}"/>
            <geometry>
                <box size="0.005 0.05 0.07"/>
            </geometry>
            <material name="blue"/>
        </visual>
        <collision>
            <origin xyz="0 0 0" rpy="0 0 ${pi/2}"/>
            <geometry>
                <box size="0.005 0.05 0.07"/>
            </geometry>
            <material name="green"/>
        </collision>
        <xacro:inertial_box mass="0.1" x="0.005" y="0.05" z="0.07">
            <origin xyz="0 0 0" rpy="0 0 0"/>
        </xacro:inertial_box>
    </link>

    <gazebo reference="left_gripper_link">
        <material>Gazebo/Blue</material>
        <dynamics damping="100" friction="200"/>
    </gazebo>

   
    <!--right gripper-->
    <joint name="right_gripper_joint" type="prismatic">
        <parent link="mn_link5"/>
        <child link="right_gripper_link"/>
        <origin xyz="0 -0.05 0.045" rpy="0 0 0"/>
        <axis xyz="0 1 0"/>
        <limit effort="100" lower="0.0" upper="0.03" velocity="100"/>
        <mimic joint="left_gripper_joint" multiplier="1.0" offset="0" />
    </joint>

    <transmission name="right_gripper_tr">
        <type>transmission_interface/SimpleTransmission</type>
        <joint name="right_gripper_joint">
            <hardwareInterface>hardware_interface/EffortJointInterface</hardwareInterface>
        </joint>
        <actuator name="motor_right_gripper">
            <hardwareInterface>hardware_interface/EffortJointInterface</hardwareInterface>
            <mechanicalReduction>1</mechanicalReduction>
        </actuator>
    </transmission>

    <link name="right_gripper_link">
        <visual>
            <origin xyz="0 0 0" rpy="0 0 ${pi/2}"/>
            <geometry>
                <box size="0.005 0.05 0.07"/>
            </geometry>
            <material name="green"/>
        </visual>
        <collision>
            <origin xyz="0 0 0" rpy="0 0 ${pi/2}"/>
            <geometry>
                <box size="0.005 0.05 0.07"/>
            </geometry>
            <material name="green"/>
        </collision>
        <xacro:inertial_box mass="0.1" x="0.005" y="0.05" z="0.07">
            <origin xyz="0 0 0" rpy="0 0 0"/>
        </xacro:inertial_box>
    </link>

    <gazebo reference="right_gripper_link">
        <material>Gazebo/Green</material>
        <dynamics damping="100" friction="200"/>
    </gazebo>

    

    <!--ROS PLUGIN-->

    <gazebo>
        <plugin name="mimic_joint_plugin" filename="libroboticsgroup_gazebo_mimic_joint_plugin.so">
            <joint>left_gripper_joint</joint>
            <mimicJoint>right_gripper_joint</mimicJoint>
            <multiplier>-1.0</multiplier>
            <offset>1</offset>
            <maxEffort>100.0</maxEffort>
        </plugin>
    </gazebo>

    <gazebo>
        <plugin name="gazebo_grasp_fix" filename="libgazebo_grasp_fix.so">
            <arm>
                <arm_name>gripper</arm_name>
                <palm_link>mn_link5</palm_link>
                <gripper_link>left_gripper_joint</gripper_link>
                <gripper_link>right_gripper_joint</gripper_link>
            </arm>
            <forces_angle_tolerance>100</forces_angle_tolerance>
            <update_rate>10</update_rate>
            <grip_count_threshold>3</grip_count_threshold>
            <max_grip_count>10</max_grip_count>
            <release_tolerance>0.001</release_tolerance>
            <disable_collisions_on_attach>false</disable_collisions_on_attach>
            <contact_topic>/contact</contact_topic>
        </plugin>
    </gazebo>

</robot>